Workbook

Sheet Summary
A1: Bangalore — Urban Planning Data Atlas
A2: Karnataka · Data from the corrected Atlas workbooks, October 2026
A4: Overall score (/100) | C4: =D14 -> 60
A5: Rank among the 8 Atlas cities | C5: 3 | D5: Static value: computed across all eight city files.
A7: Theme | B7: Indicators | C7: Rated | D7: Theme score (/100) | E7: Exceptional | F7: High | G7: Moderate-High | H7: Moderate | I7: Low-Moderate | J7: Low
A8: Economic Opportunities | B8: =COUNT('Economic Opportunities'!A5:A35) -> 29 | C8: =COUNT('Economic Opportunities'!F5:F35) -> 29 | D8: =IF(C8=0,"",ROUND((AVERAGE('Economic Opportunities'!F5:F35)-1)/5*100,0)) -> 78 | E8: =COUNTIF('Economic Opportunities'!E5:E35,"Exceptional") -> 17 | F8: =COUNTIF('Economic Opportunities'!E5:E35,"High") -> 5 | G8: =COUNTIF('Economic Opportunities'!E5:E35,"Moderate-High") -> 1 | H8: =COUNTIF('Economic Opportunities'!E5:E35,"Moderate") -> 2 | I8: =COUNTIF('Economic Opportunities'!E5:E35,"Low-Moderate") -> 1 | J8: =COUNTIF('Economic Opportunities'!E5:E35,"Low") -> 3
A9: Environment & Resources | B9: =COUNT('Environment & Resources'!A5:A55) -> 40 | C9: =COUNT('Environment & Resources'!F5:F55) -> 40 | D9: =IF(C9=0,"",ROUND((AVERAGE('Environment & Resources'!F5:F55)-1)/5*100,0)) -> 60 | E9: =COUNTIF('Environment & Resources'!E5:E55,"Exceptional") -> 9 | F9: =COUNTIF('Environment & Resources'!E5:E55,"High") -> 4 | G9: =COUNTIF('Environment & Resources'!E5:E55,"Moderate-High") -> 13 | H9: =COUNTIF('Environment & Resources'!E5:E55,"Moderate") -> 9 | I9: =COUNTIF('Environment & Resources'!E5:E55,"Low-Moderate") -> 2 | J9: =COUNTIF('Environment & Resources'!E5:E55,"Low") -> 3
A10: Governance & Technology | B10: =COUNT('Governance & Technology'!A5:A41) -> 29 | C10: =COUNT('Governance & Technology'!F5:F41) -> 29 | D10: =IF(C10=0,"",ROUND((AVERAGE('Governance & Technology'!F5:F41)-1)/5*100,0)) -> 57 | E10: =COUNTIF('Governance & Technology'!E5:E41,"Exceptional") -> 2 | F10: =COUNTIF('Governance & Technology'!E5:E41,"High") -> 4 | G10: =COUNTIF('Governance & Technology'!E5:E41,"Moderate-High") -> 12 | H10: =COUNTIF('Governance & Technology'!E5:E41,"Moderate") -> 10 | I10: =COUNTIF('Governance & Technology'!E5:E41,"Low-Moderate") -> 1 | J10: =COUNTIF('Governance & Technology'!E5:E41,"Low") -> 0
A11: Mobility & Accessibility | B11: =COUNT('Mobility & Accessibility'!A5:A43) -> 32 | C11: =COUNT('Mobility & Accessibility'!F5:F43) -> 30 | D11: =IF(C11=0,"",ROUND((AVERAGE('Mobility & Accessibility'!F5:F43)-1)/5*100,0)) -> 46 | E11: =COUNTIF('Mobility & Accessibility'!E5:E43,"Exceptional") -> 1 | F11: =COUNTIF('Mobility & Accessibility'!E5:E43,"High") -> 8 | G11: =COUNTIF('Mobility & Accessibility'!E5:E43,"Moderate-High") -> 2 | H11: =COUNTIF('Mobility & Accessibility'!E5:E43,"Moderate") -> 11 | I11: =COUNTIF('Mobility & Accessibility'!E5:E43,"Low-Moderate") -> 4 | J11: =COUNTIF('Mobility & Accessibility'!E5:E43,"Low") -> 4
A12: Social Infrastructure | B12: =COUNT('Social Infrastructure'!A5:A50) -> 35 | C12: =COUNT('Social Infrastructure'!F5:F50) -> 30 | D12: =IF(C12=0,"",ROUND((AVERAGE('Social Infrastructure'!F5:F50)-1)/5*100,0)) -> 71 | E12: =COUNTIF('Social Infrastructure'!E5:E50,"Exceptional") -> 1 | F12: =COUNTIF('Social Infrastructure'!E5:E50,"High") -> 21 | G12: =COUNTIF('Social Infrastructure'!E5:E50,"Moderate-High") -> 2 | H12: =COUNTIF('Social Infrastructure'!E5:E50,"Moderate") -> 5 | I12: =COUNTIF('Social Infrastructure'!E5:E50,"Low-Moderate") -> 1 | J12: =COUNTIF('Social Infrastructure'!E5:E50,"Low") -> 0
A13: Urban Infrastructure | B13: =COUNT('Urban Infrastructure'!A5:A46) -> 37 | C13: =COUNT('Urban Infrastructure'!F5:F46) -> 15 | D13: =IF(C13=0,"",ROUND((AVERAGE('Urban Infrastructure'!F5:F46)-1)/5*100,0)) -> 39 | E13: =COUNTIF('Urban Infrastructure'!E5:E46,"Exceptional") -> 0 | F13: =COUNTIF('Urban Infrastructure'!E5:E46,"High") -> 2 | G13: =COUNTIF('Urban Infrastructure'!E5:E46,"Moderate-High") -> 2 | H13: =COUNTIF('Urban Infrastructure'!E5:E46,"Moderate") -> 6 | I13: =COUNTIF('Urban Infrastructure'!E5:E46,"Low-Moderate") -> 3 | J13: =COUNTIF('Urban Infrastructure'!E5:E46,"Low") -> 2
A14: All themes | B14: =SUM(B8:B13) -> 202 | C14: =SUM(C8:C13) -> 173 | D14: =ROUND(SUMPRODUCT(D8:D13,C8:C13)/SUM(C8:C13),0) -> 60 | E14: =SUM(E8:E13) -> 30 | F14: =SUM(F8:F13) -> 44 | G14: =SUM(G8:G13) -> 32 | H14: =SUM(H8:H13) -> 43 | I14: =SUM(I8:I13) -> 12 | J14: =SUM(J8:J13) -> 12
A16: How to read: theme score = average rating score rescaled to 0–100 (100 = Exceptional on every rated indicator). Counts and scores are formulas over the theme sheets and update if a rating is edited.
A17: Data basis column on each sheet: Official source, Third-party source, Derived / calculated, Estimated or Unverifiable — see the Data Credibility Ranking workbook for details.

Sheet Economic Opportunities
A1: Bangalore — Economic Opportunities
A2: Values and ratings from the corrected Urban Planning Data Atlas workbooks (Oct 2026). Ratings rank the city against the other seven Atlas cities. Rating score: 6 = Exceptional … 1 = Low.
A4: S.No | B4: Topic | C4: Indicator | D4: Value | E4: Rating | F4: Rating score (1–6) | G4: Data basis | H4: Source & timeline | I4: Verification note
A5: Employment Generation
A6: 1 | B6: Employment Generation | C6: Number of Employment Hubs | D6: ~45 hubs | E6: Exceptional | F6: =IFERROR(MATCH(E6,{"Low","Low-Moderate","Moderate","Moderate-High","High","Exceptional"},0),"") -> 6 | G6: Estimated | H6: Number of employment hubs — State Industrial Development Corporations & Municipal Land-Use Master Plans, 2024–2025
A7: 2 | B7: Employment Generation | C7: Job Creation Rate (%) | D7: 8.8% | E7: Exceptional | F7: =IFERROR(MATCH(E7,{"Low","Low-Moderate","Moderate","Moderate-High","High","Exceptional"},0),"") -> 6 | G7: Estimated | H7: Job creation rate — Ministry of Labour & Employment Periodic Labour Force Survey (PLFS), 2024
A8: 3 | B8: Employment Generation | C8: Formal Employment Share (%) | D8: 45% | E8: Exceptional | F8: =IFERROR(MATCH(E8,{"Low","Low-Moderate","Moderate","Moderate-High","High","Exceptional"},0),"") -> 6 | G8: Estimated | H8: Formal employment share — Estimated from EPFO District Remittance Logs & Census Demographic Projections, 2024
A9: 4 | B9: Employment Generation | C9: Business Establishments (Total Registered) | D9: ~750,000 | E9: Exceptional | F9: =IFERROR(MATCH(E9,{"Low","Low-Moderate","Moderate","Moderate-High","High","Exceptional"},0),"") -> 6 | G9: Estimated | H9: Business establishments — Ministry of Corporate Affairs (MCA) Registry & MoMSME Udyam Database, 2024
A10: 5 | B10: Employment Generation | C10: Startup Ecosystem Accessibility | D10: ~650 | E10: Exceptional | F10: =IFERROR(MATCH(E10,{"Low","Low-Moderate","Moderate","Moderate-High","High","Exceptional"},0),"") -> 6 | G10: Estimated | H10: Startup ecosystem accessibility — Startup India Hub Central Database & Commercial Real Estate Trackers, 2024–2025
A11: 6 | B11: Employment Generation | C11: Job Growth Rate (%) | D11: 8.5% | E11: Exceptional | F11: =IFERROR(MATCH(E11,{"Low","Low-Moderate","Moderate","Moderate-High","High","Exceptional"},0),"") -> 6 | G11: Estimated | H11: Job growth rate — Directorate General of Employment (DGE) Quarterly Employment Surveys, 2024
A12: 7 | B12: Employment Generation | C12: Income Levels (Avg/Month) | D12: ~₹58,000/mo | E12: Exceptional | F12: =IFERROR(MATCH(E12,{"Low","Low-Moderate","Moderate","Moderate-High","High","Exceptional"},0),"") -> 6 | G12: Estimated | H12: Income levels — Estimated via PLFS Wage Profiles & Corporate Compensation Benchmarking Indexes, 2024
A13: 8 | B13: Employment Generation | C13: MSME Contribution (% of GDP) | D13: 22% | E13: Low | F13: =IFERROR(MATCH(E13,{"Low","Low-Moderate","Moderate","Moderate-High","High","Exceptional"},0),"") -> 1 | G13: Estimated | H13: MSME contribution — State Directorates of Economics and Statistics Annual GSDP Sectoral Reports, 2023–2024
A14: 9 | B14: Employment Generation | C14: Business Survival Rate (%, 5-Year) | D14: 62% | E14: Exceptional | F14: =IFERROR(MATCH(E14,{"Low","Low-Moderate","Moderate","Moderate-High","High","Exceptional"},0),"") -> 6 | G14: Estimated | H14: Business survival rate — Estimated based on MCA Registration vs. Winding-Up Longitudinal Studies, 2024
A15: 10 | B15: Employment Generation | C15: Employment for Vulnerable Groups (/5) | D15: 4.2 / 5 | E15: Exceptional | F15: =IFERROR(MATCH(E15,{"Low","Low-Moderate","Moderate","Moderate-High","High","Exceptional"},0),"") -> 6 | G15: Unverifiable | H15: Employment for vulnerable groups — Estimated from MoHUA Social Inclusivity Index Parameters, 2024
A16: 11 | B16: Employment Generation | C16: City GDP (GSDP/Urban GDP) | D16: ₹7,60,362 | E16: Exceptional | F16: =IFERROR(MATCH(E16,{"Low","Low-Moderate","Moderate","Moderate-High","High","Exceptional"},0),"") -> 6 | G16: Derived / calculated | H16: City GDP per capita — Delhi: Economic Survey of Delhi, per-capita income 2024-25 (₹4,93,024). Bangalore: Economic Survey of Karnataka 2023-24, Bengaluru Urban district PCI 2022-23 (₹7,60,362). Other cities: compiler estimates (unverified). | I16: Corrected: Bengaluru Urban district per-capita income 2022-23, Economic Survey of Karnataka 2023-24.
A17: 12 | B17: Employment Generation | C17: Economic Growth Rate (%) | D17: 8.5% | E17: Exceptional | F17: =IFERROR(MATCH(E17,{"Low","Low-Moderate","Moderate","Moderate-High","High","Exceptional"},0),"") -> 6 | G17: Derived / calculated | H17: Economic growth rate — State Directorates of Economics and Statistics Consolidated GDVA Profiles, 2024
A18: 13 | B18: Employment Generation | C18: Income Distribution (Gini Index) | D18: 0.35 | E18: Low | F18: =IFERROR(MATCH(E18,{"Low","Low-Moderate","Moderate","Moderate-High","High","Exceptional"},0),"") -> 1 | G18: Estimated | H18: Income distribution — NSSO Household Consumption Expenditure Survey Urban Core Splits, 2023–2024
A19: 14 | B19: Employment Generation | C19: Poverty — MPI Headcount (%) | D19: 2.8% | E19: Exceptional | F19: =IFERROR(MATCH(E19,{"Low","Low-Moderate","Moderate","Moderate-High","High","Exceptional"},0),"") -> 6 | G19: Official source | H19: Poverty — NITI Aayog National Multidimensional Poverty Index: A Progress Review 2023, district headcount ratio, NFHS-5 (2019–21). Values not re-verified to the decimal.
A20: 15 | B20: Employment Generation | C20: Industrial Areas/Zones (Area Ratio) | D20: 0.11 | E20: Moderate | F20: =IFERROR(MATCH(E20,{"Low","Low-Moderate","Moderate","Moderate-High","High","Exceptional"},0),"") -> 3 | G20: Estimated | H20: Industrial areas/zones — Estimated via Master Plans & State Industrial Development Corporation Plot Records, 2024
A21: 16 | B21: Employment Generation | C21: Connectivity to Transport Networks (/5) | D21: 4 / 5 | E21: Low-Moderate | F21: =IFERROR(MATCH(E21,{"Low","Low-Moderate","Moderate","Moderate-High","High","Exceptional"},0),"") -> 2 | G21: Unverifiable | H21: Connectivity to transport networks — Estimated via Ministry of Commerce Logistics Ease Across Different States (LEADS) Criteria, 2024
A22: 17 | B22: Employment Generation | C22: Industrial Output (% GDP Contribution) | D22: ~24% | E22: Moderate | F22: =IFERROR(MATCH(E22,{"Low","Low-Moderate","Moderate","Moderate-High","High","Exceptional"},0),"") -> 3 | G22: Estimated | H22: Industrial output — State Directorates of Economics and Statistics, Gross District Value Added (GDVA) Profiles, 2023–2024
A23: 18 | B23: Employment Generation | C23: Green Industrial Practices (%) | D23: 75% | E23: Exceptional | F23: =IFERROR(MATCH(E23,{"Low","Low-Moderate","Moderate","Moderate-High","High","Exceptional"},0),"") -> 6 | G23: Estimated | H23: Green industrial practices — State Pollution Control Boards (SPCB) Industrial Compliance Databases, 2024
A24: 19 | B24: Employment Generation | C24: Employment Generation (Cumulative Salary Index) | D24: High | E24: High | F24: =IFERROR(MATCH(E24,{"Low","Low-Moderate","Moderate","Moderate-High","High","Exceptional"},0),"") -> 5 | G24: Unverifiable | H24: Employment generation — Estimated from Annual Survey of Industries & EPFO District Registration Densities, 2024
A25: Skill Dev & Entrep
A26: 20 | B26: Skill Dev & Entrep | C26: Skill Development Centres | D26: 115 | E26: High | F26: =IFERROR(MATCH(E26,{"Low","Low-Moderate","Moderate","Moderate-High","High","Exceptional"},0),"") -> 5 | G26: Estimated | H26: Skill development centres — Ministry of Skill Development and Entrepreneurship Kaushal Vikas Portal, 2024
A27: 21 | B27: Skill Dev & Entrep | C27: Incubation/Startup Centres | D27: 160 | E27: Exceptional | F27: =IFERROR(MATCH(E27,{"Low","Low-Moderate","Moderate","Moderate-High","High","Exceptional"},0),"") -> 6 | G27: Estimated | H27: Incubation/startup centres — Startup India Hub Central Registry & Institutional Mapping, 2024
A28: 22 | B28: Skill Dev & Entrep | C28: Social Welfare Centres | D28: 124 | E28: High | F28: =IFERROR(MATCH(E28,{"Low","Low-Moderate","Moderate","Moderate-High","High","Exceptional"},0),"") -> 5 | G28: Estimated | H28: Social welfare centres — Estimated from Municipal Corporation Asset Management Ledgers, 2024
A29: 23 | B29: Skill Dev & Entrep | C29: Access for Low-Income Groups (%) | D29: 60% | E29: Moderate-High | F29: =IFERROR(MATCH(E29,{"Low","Low-Moderate","Moderate","Moderate-High","High","Exceptional"},0),"") -> 4 | G29: Estimated | H29: Access for low-income groups — National Skill Development Corporation (NSDC) Enrollment Analytics, 2024
A30: 24 | B30: Skill Dev & Entrep | C30: Gender Inclusivity (%) | D30: 48% | E30: Exceptional | F30: =IFERROR(MATCH(E30,{"Low","Low-Moderate","Moderate","Moderate-High","High","Exceptional"},0),"") -> 6 | G30: Estimated | H30: Gender inclusivity — MSDE Gender Segregated Skill Training Database Projections, 2024
A31: 25 | B31: Skill Dev & Entrep | C31: Number of Enterprises | D31: 55 | E31: Exceptional | F31: =IFERROR(MATCH(E31,{"Low","Low-Moderate","Moderate","Moderate-High","High","Exceptional"},0),"") -> 6 | G31: Estimated | H31: Number of enterprises — Ministry of Micro, Small and Medium Enterprises (MoMSME) Udyam Portal, 2024
A32: 26 | B32: Skill Dev & Entrep | C32: Startup Density (per 100k Pop) | D32: 100 | E32: High | F32: =IFERROR(MATCH(E32,{"Low","Low-Moderate","Moderate","Moderate-High","High","Exceptional"},0),"") -> 5 | G32: Derived / calculated | H32: Startup density — DPIIT-recognised startups ÷ population. Delhi 16,356 (Jan 2025); Bengaluru 13,649 (Oct 2024); Kanpur consistent with 508 in Kanpur Nagar (Oct 2023). Other cities unverified and possibly overstated. | I32: Corrected: 13,649 DPIIT-recognised startups in Bengaluru Urban + Rural (Oct 2024, Parliament reply) ÷ ~13.5 M population.
A33: 27 | B33: Skill Dev & Entrep | C33: Ease of Doing Business (/5) | D33: 4.5 / 5 | E33: High | F33: =IFERROR(MATCH(E33,{"Low","Low-Moderate","Moderate","Moderate-High","High","Exceptional"},0),"") -> 5 | G33: Unverifiable | H33: Ease of doing business — DPIIT Business Reform Action Plan (BRAP) Adjustments, 2023–2024
A34: 28 | B34: Skill Dev & Entrep | C34: Incubation Ecosystem (Hubs/Accelerators) | D34: ~650 | E34: Exceptional | F34: =IFERROR(MATCH(E34,{"Low","Low-Moderate","Moderate","Moderate-High","High","Exceptional"},0),"") -> 6 | G34: Estimated | H34: Incubation ecosystem — Same definition as sheet i) indicator (e); harmonised to that value (estimated, unverified). Narrow incubator count is (b). | I34: Harmonised: Same definition as sheet i) (e) — incubators + co-working + startup hubs; harmonised to one value.
A35: 29 | B35: Skill Dev & Entrep | C35: MSME Contribution (% of GDP) | D35: 22% | E35: Low | F35: =IFERROR(MATCH(E35,{"Low","Low-Moderate","Moderate","Moderate-High","High","Exceptional"},0),"") -> 1 | G35: Estimated | H35: MSME contribution — Harmonised with sheet i) indicator (h): State Directorates of Economics and Statistics GSDP sectoral reports, 2023–2024 (compiler estimate, unverified). | I35: Harmonised: Harmonised with sheet i) indicator (h) so one value is used per city.
A37: Blue bold value = corrected or updated after cross-verification; amber bold = flagged for review. Full change history is in the Change Log sheet of each theme workbook.

Sheet Environment & Resources
A1: Bangalore — Environment & Resources
A2: Values and ratings from the corrected Urban Planning Data Atlas workbooks (Oct 2026). Ratings rank the city against the other seven Atlas cities. Rating score: 6 = Exceptional … 1 = Low.
A4: S.No | B4: Topic | C4: Indicator | D4: Value | E4: Rating | F4: Rating score (1–6) | G4: Data basis | H4: Source & timeline | I4: Verification note
A5: Clean Green Surroundings
A6: 1 | B6: Clean Green Surroundings | C6: Green Cover — Forest & Tree Proxy (%) | D6: 12% | E6: Moderate-High | F6: =IFERROR(MATCH(E6,{"Low","Low-Moderate","Moderate","Moderate-High","High","Exceptional"},0),"") -> 4 | G6: Derived / calculated | H6: Green cover — Proxy based on FSI India State of Forest Report (forest and tree cover), not a parks inventory. Delhi forest cover alone is 194.15 km² ≈ 13% of 1,483 km² (ISFR 2023). Values unverified.
A7: 2 | B7: Clean Green Surroundings | C7: Visual Hygiene Index (/5) | D7: 3.6 | E7: Moderate | F7: =IFERROR(MATCH(E7,{"Low","Low-Moderate","Moderate","Moderate-High","High","Exceptional"},0),"") -> 3 | G7: Unverifiable | H7: Visual hygiene index — MoHUA Swachh Survekshan Citizen Feedback Component, 2023–2024
A8: Water Conservation
A9: 3 | B9: Water Conservation | C9: RWH Coverage (%) | D9: 65% | E9: Exceptional | F9: =IFERROR(MATCH(E9,{"Low","Low-Moderate","Moderate","Moderate-High","High","Exceptional"},0),"") -> 6 | G9: Estimated | H9: RWH coverage — CGWB / Municipal RWH Compliance Audits, 2024
A10: 4 | B10: Water Conservation | C10: Freshwater Recharge Capacity (ML/yr) | D10: 1,200 ML/yr | E10: Exceptional | F10: =IFERROR(MATCH(E10,{"Low","Low-Moderate","Moderate","Moderate-High","High","Exceptional"},0),"") -> 6 | G10: Estimated | H10: Freshwater recharge capacity — Estimated via CGWB Hydrological Model Projections, 2024
A11: 5 | B11: Water Conservation | C11: Coverage in Critical Zones (%) | D11: 78% | E11: Exceptional | F11: =IFERROR(MATCH(E11,{"Low","Low-Moderate","Moderate","Moderate-High","High","Exceptional"},0),"") -> 6 | G11: Estimated | H11: Coverage in critical zones — State Ground Water Department Over-exploited Block Action Trackers, 2024
A12: 6 | B12: Water Conservation | C12: Integration with Urban Drainage (%) | D12: 40% | E12: Exceptional | F12: =IFERROR(MATCH(E12,{"Low","Low-Moderate","Moderate","Moderate-High","High","Exceptional"},0),"") -> 6 | G12: Estimated | H12: Integration with urban drainage — Estimated based on Atal Mission (AMRUT) Stormwater Drainage Plans, 2024
A13: 7 | B13: Water Conservation | C13: Adoption in Low- Income Areas (%) | D13: 22% | E13: Exceptional | F13: =IFERROR(MATCH(E13,{"Low","Low-Moderate","Moderate","Moderate-High","High","Exceptional"},0),"") -> 6 | G13: Estimated | H13: Adoption in low-income areas — Estimated via Slum Upgrading & Urban Water Supply Baseline Surveys, 2024
A14: Resource-Efficient Econ
A15: 8 | B15: Resource-Efficient Econ | C15: Recycling Rate (%) | D15: 55% | E15: Moderate-High | F15: =IFERROR(MATCH(E15,{"Low","Low-Moderate","Moderate","Moderate-High","High","Exceptional"},0),"") -> 4 | G15: Derived / calculated | H15: Recycling rate — CPCB Co-processing and Material Recovery Facility Annual Registries, 2023–2024
A16: 9 | B16: Resource-Efficient Econ | C16: Energy Recovery from Waste (%) | D16: 12% | E16: Moderate | F16: =IFERROR(MATCH(E16,{"Low","Low-Moderate","Moderate","Moderate-High","High","Exceptional"},0),"") -> 3 | G16: Derived / calculated | H16: Energy recovery from waste — Ministry of New and Renewable Energy (MNRE) WtE Plant Trackers, 2024
A17: 10 | B17: Resource-Efficient Econ | C17: Carbon Reduction (tCO2/year) | D17: ~32,000 | E17: High | F17: =IFERROR(MATCH(E17,{"Low","Low-Moderate","Moderate","Moderate-High","High","Exceptional"},0),"") -> 5 | G17: Estimated | H17: Carbon reduction — Climate Smart Cities Assessment Framework (CSCAF) Models, 2024
A18: Minimal Waste Adoption
A19: 11 | B19: Minimal Waste Adoption | C19: Existence of Zero- Waste Policy | D19: Yes | E19: High | F19: =IFERROR(MATCH(E19,{"Low","Low-Moderate","Moderate","Moderate-High","High","Exceptional"},0),"") -> 5 | G19: Unverifiable | H19: Existence of zero-waste policy — State Urban Development Gazette Notifications, 2023
A20: 12 | B20: Minimal Waste Adoption | C20: Stakeholder Participation (%) | D20: 68% | E20: Moderate-High | F20: =IFERROR(MATCH(E20,{"Low","Low-Moderate","Moderate","Moderate-High","High","Exceptional"},0),"") -> 4 | G20: Estimated | H20: Stakeholder participation — MoHUA Bulk Waste Generator Enforcement Monitoring Dashboards, 2024
A21: 13 | B21: Minimal Waste Adoption | C21: Policy Implementation Rate (%) | D21: 78% | E21: Moderate-High | F21: =IFERROR(MATCH(E21,{"Low","Low-Moderate","Moderate","Moderate-High","High","Exceptional"},0),"") -> 4 | G21: Estimated | H21: Policy implementation rate — State Environmental Action Plan Annual Milestones, 2024
A22: 14 | B22: Minimal Waste Adoption | C22: Lifecycle Waste Reduction (%) | D22: 9% | E22: Moderate-High | F22: =IFERROR(MATCH(E22,{"Low","Low-Moderate","Moderate","Moderate-High","High","Exceptional"},0),"") -> 4 | G22: Derived / calculated | H22: Lifecycle waste reduction — Derived from Municipal Per Capita Daily Inflow Longitudinal Tracking, 2023–2024
A23: Climate-Resilient Cities
A24: 15 | B24: Climate-Resilient Cities | C24: Nature-Based Solutions Adoption (%) | D24: 18% | E24: Moderate-High | F24: =IFERROR(MATCH(E24,{"Low","Low-Moderate","Moderate","Moderate-High","High","Exceptional"},0),"") -> 4 | G24: Estimated | H24: Nature-based solutions adoption — National Mission on Sustainable Habitat Progress Audits, 2024
A25: 16 | B25: Climate-Resilient Cities | C25: Policy Integration Level (/5) | D25: 4 / 5 | E25: Moderate-High | F25: =IFERROR(MATCH(E25,{"Low","Low-Moderate","Moderate","Moderate-High","High","Exceptional"},0),"") -> 4 | G25: Unverifiable | H25: Policy integration level — CSCAF Urban Climate Resiliency Integration Indices, 2024
A26: Renewable Energy
A27: 17 | B27: Renewable Energy | C27: Grid Integration of Renewables (%) | D27: 48.0% | E27: Exceptional | F27: =IFERROR(MATCH(E27,{"Low","Low-Moderate","Moderate","Moderate-High","High","Exceptional"},0),"") -> 6 | G27: Estimated | H27: Grid integration of renewables — Central Electricity Authority (CEA) Power Mix Data, 2024
A28: Sanitation & Drainage
A29: 18 | B29: Sanitation & Drainage | C29: STP Capacity (MLD) | D29: 1,450 MLD (City) | E29: High | F29: =IFERROR(MATCH(E29,{"Low","Low-Moderate","Moderate","Moderate-High","High","Exceptional"},0),"") -> 5 | G29: Official source | H29: STP capacity — CPCB National STP Inventory, 2023–2024; Delhi: DPCC sewage status, Mar 2025 (764 MGD = 3,474 MLD)
A30: 19 | B30: Sanitation & Drainage | C30: Sewerage Network Coverage (%) | D30: 78% | E30: Moderate | F30: =IFERROR(MATCH(E30,{"Low","Low-Moderate","Moderate","Moderate-High","High","Exceptional"},0),"") -> 3 | G30: Estimated | H30: Sewerage network coverage — Ministry of Housing and Urban Affairs (MoHUA) City Development Plans, 2023
A31: 20 | B31: Sanitation & Drainage | C31: Household Sewer Connections (%) | D31: 75% | E31: Moderate | F31: =IFERROR(MATCH(E31,{"Low","Low-Moderate","Moderate","Moderate-High","High","Exceptional"},0),"") -> 3 | G31: Estimated | H31: Household sewer connections — Estimated based on Municipal AMRUT Project Progress Records, 2024
A32: 21 | B32: Sanitation & Drainage | C32: Coverage in Informal Areas (%) | D32: 50% | E32: Moderate-High | F32: =IFERROR(MATCH(E32,{"Low","Low-Moderate","Moderate","Moderate-High","High","Exceptional"},0),"") -> 4 | G32: Estimated | H32: Coverage in informal areas — Estimated based on Slum Free City Action Plan baselines, 2024
A33: 22 | B33: Sanitation & Drainage | C33: Flood-Prone Area Coverage (%) | D33: 55% | E33: Moderate | F33: =IFERROR(MATCH(E33,{"Low","Low-Moderate","Moderate","Moderate-High","High","Exceptional"},0),"") -> 3 | G33: Estimated | H33: Flood-prone area coverage — Estimated via Municipal Stormwater Drainage Master Plans, 2024
A34: 23 | B34: Sanitation & Drainage | C34: Sewage Treatment Efficiency (%) | D34: 88% | E34: Moderate-High | F34: =IFERROR(MATCH(E34,{"Low","Low-Moderate","Moderate","Moderate-High","High","Exceptional"},0),"") -> 4 | G34: Derived / calculated | H34: Sewage treatment efficiency — Derived from CPCB Wastewater Generation vs Treated Capacity Estimates, 2023–2024
A35: 24 | B35: Sanitation & Drainage | C35: Water Quality Post- Treatment (BOD/COD) | D35: BOD: ~10 COD: ~45 | E35: Moderate-High | F35: =IFERROR(MATCH(E35,{"Low","Low-Moderate","Moderate","Moderate-High","High","Exceptional"},0),"") -> 4 | G35: Estimated | H35: Water quality posttreatment — State Pollution Control Boards (SPCB) Treated Effluent Monthly Monitoring, 2024
A36: Air Quality Monitoring
A37: 25 | B37: Air Quality Monitoring | C37: Monitoring Density (Stations/km²) | D37: 0.020 | E37: Low-Moderate | F37: =IFERROR(MATCH(E37,{"Low","Low-Moderate","Moderate","Moderate-High","High","Exceptional"},0),"") -> 2 | G37: Derived / calculated | H37: Monitoring density — Harmonised with sheet x) (a): CPCB CAAQMS station count ÷ city area, 2024. Delhi ~37 stations ÷ 1,483 km² ≈ 0.025. | I37: Harmonised: Harmonised with sheet x) (a), calculated from CPCB CAAQMS station counts ÷ city area.
A38: Waste Mgmt Adoption
A39: 26 | B39: Waste Mgmt Adoption | C39: Waste Collection Coverage (%) | D39: 98% | E39: Moderate | F39: =IFERROR(MATCH(E39,{"Low","Low-Moderate","Moderate","Moderate-High","High","Exceptional"},0),"") -> 3 | G39: Derived / calculated | H39: Waste collection coverage — MoHUA Swachh Survekshan Assessment Dashboard, 2023
A40: 27 | B40: Waste Mgmt Adoption | C40: Recycling Rate (%) | D40: 55% | E40: Moderate-High | F40: =IFERROR(MATCH(E40,{"Low","Low-Moderate","Moderate","Moderate-High","High","Exceptional"},0),"") -> 4 | G40: Derived / calculated | H40: Recycling rate — MoHUA Swachh Survekshan Solid Waste Processing Metrics, 2023
A41: Pollution Control
...

Sheet Governance & Technology
A1: Bangalore — Governance & Technology
A2: Values and ratings from the corrected Urban Planning Data Atlas workbooks (Oct 2026). Ratings rank the city against the other seven Atlas cities. Rating score: 6 = Exceptional … 1 = Low.
A4: S.No | B4: Topic | C4: Indicator | D4: Value | E4: Rating | F4: Rating score (1–6) | G4: Data basis | H4: Source & timeline | I4: Verification note
A5: Inclusive Communities
A6: 1 | B6: Inclusive Communities | C6: Reported Communal Disturbance Cases | D6: 1 | E6: Moderate-High | F6: =IFERROR(MATCH(E6,{"Low","Low-Moderate","Moderate","Moderate-High","High","Exceptional"},0),"") -> 4 | G6: Official source | H6: Reported communal disturbance cases — National Crime Records Bureau (NCRB) - Crime in India Annual Report, 2023–2024
A7: 2 | B7: Inclusive Communities | C7: Availability of Community Centers | D7: 1.2 | E7: Moderate | F7: =IFERROR(MATCH(E7,{"Low","Low-Moderate","Moderate","Moderate-High","High","Exceptional"},0),"") -> 3 | G7: Estimated | H7: Availability of community centers — Estimated from Municipal Infrastructure Asset Registers & Ward Master Plans, 2024
A8: 3 | B8: Inclusive Communities | C8: Social Cohesion Index (/5) | D8: 4.1 | E8: Moderate | F8: =IFERROR(MATCH(E8,{"Low","Low-Moderate","Moderate","Moderate-High","High","Exceptional"},0),"") -> 3 | G8: Unverifiable | H8: Social cohesion index — Compiler estimate (unverified). No MoHUA Ease of Living perception-survey results for 2023–24 have been published; the latest published edition is EoLI 2020.
A9: Citizen Participation
A10: 4 | B10: Citizen Participation | C10: Digital Governance Platforms (Number) | D10: 11 | E10: Moderate-High | F10: =IFERROR(MATCH(E10,{"Low","Low-Moderate","Moderate","Moderate-High","High","Exceptional"},0),"") -> 4 | G10: Estimated | H10: Digital governance platforms — National e-Governance Division (NeGD) / Smart Cities Mission IT Progress Trackers, 2024
A11: 5 | B11: Citizen Participation | C11: Grievance Resolution Rate (%) | D11: 84% | E11: Moderate | F11: =IFERROR(MATCH(E11,{"Low","Low-Moderate","Moderate","Moderate-High","High","Exceptional"},0),"") -> 3 | G11: Estimated | H11: Grievance resolution rate — MoHUA Smart Cities Mission Central Management Information System (MIS), 2024
A12: Transparent Governance
A13: 6 | B13: Transparent Governance | C13: Citizen Satisfaction with Governance (%) | D13: 74% | E13: Moderate-High | F13: =IFERROR(MATCH(E13,{"Low","Low-Moderate","Moderate","Moderate-High","High","Exceptional"},0),"") -> 4 | G13: Unverifiable | H13: Citizen satisfaction with governance — Compiler estimate (unverified). No MoHUA Ease of Living perception-survey results for 2023–24 have been published; the latest published edition is EoLI 2020. | I13: Unverified: No published 2023–24 survey behind this value.
A14: 7 | B14: Transparent Governance | C14: Policy Implementation Rate (%) | D14: 80% | E14: Moderate | F14: =IFERROR(MATCH(E14,{"Low","Low-Moderate","Moderate","Moderate-High","High","Exceptional"},0),"") -> 3 | G14: Estimated | H14: Policy implementation rate — Estimated based on Smart Cities Mission Project Milestone Progress Dashboards, 2024
A15: 8 | B15: Transparent Governance | C15: Representation Diversity (%) | D15: 50% | E15: Moderate | F15: =IFERROR(MATCH(E15,{"Low","Low-Moderate","Moderate","Moderate-High","High","Exceptional"},0),"") -> 3 | G15: Official source | H15: Representation diversity — Statutory reservation of municipal council seats for women (State Election Commission notifications). Delhi 50% per SEC Delhi press note, 4 Nov 2022. Pune and Bengaluru had no elected council in 2023–24; their values are notional. | I15: Notional: Statutory 50% reservation; BBMP has had no elected council since Sept 2020, so 2023–24 value is notional.
A16: Real-Time City Mgmt
A17: 9 | B17: Real-Time City Mgmt | C17: Area Coverage (ICCC Sufficiency, %) | D17: 88% | E17: Moderate-High | F17: =IFERROR(MATCH(E17,{"Low","Low-Moderate","Moderate","Moderate-High","High","Exceptional"},0),"") -> 4 | G17: Estimated | H17: Area coverage — National Smart Cities Mission (SCM) Integrated Command and Control Centre Database, 2024
A18: 10 | B18: Real-Time City Mgmt | C18: Area Coverage (CCTV, %) | D18: 82% | E18: High | F18: =IFERROR(MATCH(E18,{"Low","Low-Moderate","Moderate","Moderate-High","High","Exceptional"},0),"") -> 5 | G18: Estimated | H18: Area coverage — City Police IT & Surveillance Wing Deployment Audits, 2024
A19: 11 | B19: Real-Time City Mgmt | C19: Incident Response Time (min) | D19: 18 min (City) | E19: Low-Moderate | F19: =IFERROR(MATCH(E19,{"Low","Low-Moderate","Moderate","Moderate-High","High","Exceptional"},0),"") -> 2 | G19: Estimated | H19: Incident response time — State Integrated Emergency Response Logs (Dial 112 / ICCC Data), 2024
A20: Digital Public Services
A21: 12 | B21: Digital Public Services | C21: Total Digital Kiosks (per Population) | D21: 5.8 | E21: High | F21: =IFERROR(MATCH(E21,{"Low","Low-Moderate","Moderate","Moderate-High","High","Exceptional"},0),"") -> 5 | G21: Estimated | H21: Total number of digital kiosks — Estimated via Municipal Smart Infrastructure Asset Registers, 2024
A22: 13 | B22: Digital Public Services | C22: Digital Participation & Transaction Penetration (%) | D22: 94% | E22: Exceptional | F22: =IFERROR(MATCH(E22,{"Low","Low-Moderate","Moderate","Moderate-High","High","Exceptional"},0),"") -> 6 | G22: Estimated | H22: Digital Participation and Transaction Penetration — RBI Digital Payments Index & NPCI Geo-transaction Projections, 2024
A23: 14 | B23: Digital Public Services | C23: Accessibility for Small Vendors (%) | D23: 96% | E23: Exceptional | F23: =IFERROR(MATCH(E23,{"Low","Low-Moderate","Moderate","Moderate-High","High","Exceptional"},0),"") -> 6 | G23: Estimated | H23: Accessibility for small vendors — Ministry of Housing and Urban Affairs (MoHUA) PM SVANidhi Onboarding Portals, 2024
A24: 15 | B24: Digital Public Services | C24: Hotspot Density (Wi-Fi/km²) | D24: 0.72 | E24: High | F24: =IFERROR(MATCH(E24,{"Low","Low-Moderate","Moderate","Moderate-High","High","Exceptional"},0),"") -> 5 | G24: Estimated | H24: Hotspot density — Department of Telecommunications (DoT) & State IT Department Deployment Registries, 2024
A25: 16 | B25: Digital Public Services | C25: Network Coverage (4G/5G, %) | D25: 99% | E25: Moderate-High | F25: =IFERROR(MATCH(E25,{"Low","Low-Moderate","Moderate","Moderate-High","High","Exceptional"},0),"") -> 4 | G25: Estimated | H25: Network coverage — Telecom Regulatory Authority of India (TRAI) Quality of Service (QoS) Reports, 2024
A26: Disaster Mitigation
A27: 17 | B27: Disaster Mitigation | C27: Sensor Density in Hazard Zones | D27: 1.1 | E27: Moderate | F27: =IFERROR(MATCH(E27,{"Low","Low-Moderate","Moderate","Moderate-High","High","Exceptional"},0),"") -> 3 | G27: Estimated | H27: Sensor density in hazard zones — Estimated from Municipal Smart Drainage & Disaster Management Sensor Registries, 2024
A28: 18 | B28: Disaster Mitigation | C28: Binary Coverage of Mitigation Centres (%) | D28: 75% | E28: Moderate | F28: =IFERROR(MATCH(E28,{"Low","Low-Moderate","Moderate","Moderate-High","High","Exceptional"},0),"") -> 3 | G28: Estimated | H28: Binary coverage of mitigation centres — National Disaster Management Authority (NDMA) Resilient Cities Structural Audits, 2024
A29: 19 | B29: Disaster Mitigation | C29: Early Warning Dissemination Coverage (%) | D29: 85% | E29: Moderate | F29: =IFERROR(MATCH(E29,{"Low","Low-Moderate","Moderate","Moderate-High","High","Exceptional"},0),"") -> 3 | G29: Estimated | H29: Early warning dissemination coverage — State Disaster Management Authority (SDMA) Emergency Broadcast Tracking, 2024
A30: 20 | B30: Disaster Mitigation | C30: Emergency Infrastructure (Number) | D30: 80 | E30: Moderate-High | F30: =IFERROR(MATCH(E30,{"Low","Low-Moderate","Moderate","Moderate-High","High","Exceptional"},0),"") -> 4 | G30: Estimated | H30: Emergency infrastructure — Estimated based on State Disaster Management Authority (SDMA) Shelter Inventories, 2024
A31: 21 | B31: Disaster Mitigation | C31: Investment in Flood Mitigation (% Budget) | D31: 4.2% | E31: High | F31: =IFERROR(MATCH(E31,{"Low","Low-Moderate","Moderate","Moderate-High","High","Exceptional"},0),"") -> 5 | G31: Estimated | H31: Investment in flood mitigation — Combined Municipal Corporation Annual Budget Allocations, 2024–2025
A32: Citizen Satisfaction
A33: 22 | B33: Citizen Satisfaction | C33: Citizen Satisfaction Index (/5) | D33: 3.8 | E33: Moderate-High | F33: =IFERROR(MATCH(E33,{"Low","Low-Moderate","Moderate","Moderate-High","High","Exceptional"},0),"") -> 4 | G33: Unverifiable | H33: Citizen satisfaction index — Compiler estimate (unverified). No MoHUA Ease of Living perception-survey results for 2023–24 have been published; the latest published edition is EoLI 2020.
A34: Safe Public Spaces
A35: 23 | B35: Safe Public Spaces | C35: Police Personnel Strength (per 100k) | D35: 220 | E35: Moderate-High | F35: =IFERROR(MATCH(E35,{"Low","Low-Moderate","Moderate","Moderate-High","High","Exceptional"},0),"") -> 4 | G35: Derived / calculated | H35: Police personnel strength — Bureau of Police Research and Development (BPR&D) - Data on Police Organizations, 2024
A36: 24 | B36: Safe Public Spaces | C36: Vehicle-to-Population Ratio (per 100k) | D36: 32.0 | E36: Moderate-High | F36: =IFERROR(MATCH(E36,{"Low","Low-Moderate","Moderate","Moderate-High","High","Exceptional"},0),"") -> 4 | G36: Estimated | H36: Vehicle-to- population ratio — Estimated from BPR&D Fleet Allocation and Modernization Statistics, 2024
A37: 25 | B37: Safe Public Spaces | C37: Response Unit Coverage (%) | D37: 70% | E37: Moderate | F37: =IFERROR(MATCH(E37,{"Low","Low-Moderate","Moderate","Moderate-High","High","Exceptional"},0),"") -> 3 | G37: Estimated | H37: Response unit coverage — City Police ICCC Logistical Network GIS Audits, 2024
A38: 26 | B38: Safe Public Spaces | C38: Charge-sheeting Rate (%) | D38: 70% | E38: Moderate | F38: =IFERROR(MATCH(E38,{"Low","Low-Moderate","Moderate","Moderate-High","High","Exceptional"},0),"") -> 3 | G38: Derived / calculated | H38: Charge-sheeting rate — NCRB Crime in India (Metropolitan Cities). NCRB publishes a charge-sheeting rate, not a "clearance rate"; values not re-verified, 2023–2024
A39: 27 | B39: Safe Public Spaces | C39: Crowd Incident Mgmt Success (%) | D39: 99.0% (City) | E39: Moderate-High | F39: =IFERROR(MATCH(E39,{"Low","Low-Moderate","Moderate","Moderate-High","High","Exceptional"},0),"") -> 4 | G39: Unverifiable | H39: Crowd incident management success — State Home Department Law & Order Annual Reviews, 2024
A40: 28 | B40: Safe Public Spaces | C40: Integration with ICCC (%) | D40: 82% | E40: Moderate-High | F40: =IFERROR(MATCH(E40,{"Low","Low-Moderate","Moderate","Moderate-High","High","Exceptional"},0),"") -> 4 | G40: Estimated | H40: Integration with ICCC — National Smart Cities Mission Project Completion Tracking Database, 2024
A41: 29 | B41: Safe Public Spaces | C41: Gender-Sensitive Policing (%) | D41: 58% | E41: Moderate-High | F41: =IFERROR(MATCH(E41,{"Low","Low-Moderate","Moderate","Moderate-High","High","Exceptional"},0),"") -> 4 | G41: Estimated | H41: Gender-sensitive policing — BPR&D Women in Police Empowerment Initiatives Progress Reports, 2024
...

Sheet Mobility & Accessibility
A1: Bangalore — Mobility & Accessibility
A2: Values and ratings from the corrected Urban Planning Data Atlas workbooks (Oct 2026). Ratings rank the city against the other seven Atlas cities. Rating score: 6 = Exceptional … 1 = Low.
A4: S.No | B4: Topic | C4: Indicator | D4: Value | E4: Rating | F4: Rating score (1–6) | G4: Data basis | H4: Source & timeline | I4: Verification note
A5: Road Connectivity
A6: 1 | B6: Road Connectivity | C6: Length of Arterial Roads | D6: Art: 280 km | Sub: 410 km | E6: Moderate | F6: =IFERROR(MATCH(E6,{"Low","Low-Moderate","Moderate","Moderate-High","High","Exceptional"},0),"") -> 3 | G6: Estimated | H6: CMP Bengaluru / DULT (2025)
A7: 2 | B7: Road Connectivity | C7: Expressway & Ring Connectivity | D7: NE 7 Link; Choked Radial ORR | E7: Moderate | F7: =IFERROR(MATCH(E7,{"Low","Low-Moderate","Moderate","Moderate-High","High","Exceptional"},0),"") -> 3 | G7: Estimated | H7: CMP Bengaluru / DULT (2025)
A8: 3 | B8: Road Connectivity | C8: Road Capacity Adequacy (Existing/URDPFI %) | D8: 64.2% (35.8% Deficit) | E8: Low | F8: =IFERROR(MATCH(E8,{"Low","Low-Moderate","Moderate","Moderate-High","High","Exceptional"},0),"") -> 1 | G8: Estimated | H8: CMP Bengaluru / DULT (2025)
A9: 4 | B9: Road Connectivity | C9: Level of Service (LoS) (Flow & Speed Parameters) | D9: Severe Bottlenecks | 12-15 km/h | E9: Low | F9: =IFERROR(MATCH(E9,{"Low","Low-Moderate","Moderate","Moderate-High","High","Exceptional"},0),"") -> 1 | G9: Third-party source | H9: CMP Bengaluru / DULT (2025)
A10: Congestion & Free Flow
A11: 5 | B11: Congestion & Free Flow | C11: Arterial Road Coverage (% Under Traffic Controls) | D11: 44% | E11: Moderate | F11: =IFERROR(MATCH(E11,{"Low","Low-Moderate","Moderate","Moderate-High","High","Exceptional"},0),"") -> 3 | G11: Estimated | H11: TomTom Traffic Index / BTP Analytics (2025)
A12: 6 | B12: Congestion & Free Flow | C12: Congestion Index (Peak vs Free-Flow Time) | D12: 1.74x (TomTom 2025: 74.4%) | E12: Low-Moderate | F12: =IFERROR(MATCH(E12,{"Low","Low-Moderate","Moderate","Moderate-High","High","Exceptional"},0),"") -> 2 | G12: Third-party source | H12: TomTom Traffic Index / BTP Analytics (2025) | I12: Corrected: TomTom Traffic Index 2025 congestion level 74.4%.
A13: 7 | B13: Congestion & Free Flow | C13: Road Discipline Index (User Compliance Score/100) | D13: 55 / 100 | E13: Low-Moderate | F13: =IFERROR(MATCH(E13,{"Low","Low-Moderate","Moderate","Moderate-High","High","Exceptional"},0),"") -> 2 | G13: Unverifiable | H13: TomTom Traffic Index / BTP Analytics (2025)
A14: Cycling Infrastructure
A15: 8 | B15: Cycling Infrastructure | C15: Cycle Track Infrastructure (Dedicated Active Length) | D15: 34 km | E15: Low-Moderate | F15: =IFERROR(MATCH(E15,{"Low","Low-Moderate","Moderate","Moderate-High","High","Exceptional"},0),"") -> 2 | G15: Estimated | H15: DULT NMT Design Manual / BBMP (2025)
A16: 9 | B16: Cycling Infrastructure | C16: Cycle Parking Facilities (Registered Stations) | D16: 24 Stations | E16: Moderate | F16: =IFERROR(MATCH(E16,{"Low","Low-Moderate","Moderate","Moderate-High","High","Exceptional"},0),"") -> 3 | G16: Estimated | H16: DULT NMT Design Manual / BBMP (2025)
A17: 10 | B17: Cycling Infrastructure | C17: Quality & Comfort Index (Composite Score/100) | D17: 48 / 100 | E17: Low-Moderate | F17: =IFERROR(MATCH(E17,{"Low","Low-Moderate","Moderate","Moderate-High","High","Exceptional"},0),"") -> 2 | G17: Unverifiable | H17: DULT NMT Design Manual / BBMP (2025)
A18: Pedestrian Footpaths
A19: 11 | B19: Pedestrian Footpaths | C19: Footpath Coverage (% Roads with Sidewalks) | D19: 62% | E19: High | F19: =IFERROR(MATCH(E19,{"Low","Low-Moderate","Moderate","Moderate-High","High","Exceptional"},0),"") -> 5 | G19: Estimated | H19: ITDP Footpath Performance Trackers (2025)
A20: 12 | B20: Pedestrian Footpaths | C20: NMT Zones Area (Pedestrian-Only Spaces) | D20: 8 hectares | E20: Moderate | F20: =IFERROR(MATCH(E20,{"Low","Low-Moderate","Moderate","Moderate-High","High","Exceptional"},0),"") -> 3 | G20: Estimated | H20: ITDP Footpath Performance Trackers (2025)
A21: 13 | B21: Pedestrian Footpaths | C21: Walkability Index (Continuity & Safety/100) | D21: 64 / 100 | E21: Moderate-High | F21: =IFERROR(MATCH(E21,{"Low","Low-Moderate","Moderate","Moderate-High","High","Exceptional"},0),"") -> 4 | G21: Unverifiable | H21: ITDP Footpath Performance Trackers (2025)
A22: 14 | B22: Pedestrian Footpaths | C22: Universal Accessibility (% Compliant Ramps/Tactile) | D22: 48% | E22: Moderate | F22: =IFERROR(MATCH(E22,{"Low","Low-Moderate","Moderate","Moderate-High","High","Exceptional"},0),"") -> 3 | G22: Estimated | H22: ITDP Footpath Performance Trackers (2025)
A23: 15 | B23: Pedestrian Footpaths | C23: Comfort Index (Shade & Furniture Score/100) | D23: 58 / 100 | E23: High | F23: =IFERROR(MATCH(E23,{"Low","Low-Moderate","Moderate","Moderate-High","High","Exceptional"},0),"") -> 5 | G23: Unverifiable | H23: ITDP Footpath Performance Trackers (2025)
A24: Mass Public Transport
A25: 16 | B25: Mass Public Transport | C25: MRT System Presence (Metro / BRT / LRT) | D25: Metro Active (BMRCL) | E25: High | F25: =IFERROR(MATCH(E25,{"Low","Low-Moderate","Moderate","Moderate-High","High","Exceptional"},0),"") -> 5 | G25: Official source | H25: BMRCL Operational Statistics Grid (2025)
A26: 17 | B26: Mass Public Transport | C26: Coverage of MRT Network (% Served Population) | D26: 38% | E26: Moderate | F26: =IFERROR(MATCH(E26,{"Low","Low-Moderate","Moderate","Moderate-High","High","Exceptional"},0),"") -> 3 | G26: Estimated | H26: BMRCL Operational Statistics Grid (2025)
A27: 18 | B27: Mass Public Transport | C27: Proximity to MRT Stations (Avg Mile-to-Mile Distance) | D27: 1.4 KM | E27: High | F27: =IFERROR(MATCH(E27,{"Low","Low-Moderate","Moderate","Moderate-High","High","Exceptional"},0),"") -> 5 | G27: Estimated | H27: BMRCL Operational Statistics Grid (2025)
A28: 19 | B28: Mass Public Transport | C28: Ridership / Footfall (Avg Daily/Design Capacity %) | D28: 84% | E28: High | F28: =IFERROR(MATCH(E28,{"Low","Low-Moderate","Moderate","Moderate-High","High","Exceptional"},0),"") -> 5 | G28: Estimated | H28: BMRCL Operational Statistics Grid (2025)
A29: 20 | B29: Mass Public Transport | C29: Travel Time Efficiency (Avg Time Saved/10KM) | D29: 38 Mins | E29: Not rated | F29: =IFERROR(MATCH(E29,{"Low","Low-Moderate","Moderate","Moderate-High","High","Exceptional"},0),"") | G29: Estimated | H29: BMRCL Operational Statistics Grid (2025)
A30: 21 | B30: Mass Public Transport | C30: Accessibility for Vulnerable Groups (Compliance Score/100) | D30: 82 / 100 | E30: Not rated | F30: =IFERROR(MATCH(E30,{"Low","Low-Moderate","Moderate","Moderate-High","High","Exceptional"},0),"") | G30: Unverifiable | H30: BMRCL Operational Statistics Grid (2025)
A31: Intelligent Systems & Hubs
A32: 22 | B32: Intelligent Systems & Hubs | C32: Airport Connectivity (National & International) | D32: Primary Hub (BIAL); T1 & T2 | E32: Exceptional | F32: =IFERROR(MATCH(E32,{"Low","Low-Moderate","Moderate","Moderate-High","High","Exceptional"},0),"") -> 6 | G32: Official source | H32: BIAL / Bangalore Traffic Management Plan (2025)
A33: 23 | B33: Intelligent Systems & Hubs | C33: Waterways Connectivity (National & Internal Links) | D33: Absent | E33: Low | F33: =IFERROR(MATCH(E33,{"Low","Low-Moderate","Moderate","Moderate-High","High","Exceptional"},0),"") -> 1 | G33: Official source | H33: BIAL / Bangalore Traffic Management Plan (2025)
A34: 24 | B34: Intelligent Systems & Hubs | C34: Intelligent Traffic Systems (ITS) (% of Signalized Intersections) | D34: 62% (AI Management) | E34: High | F34: =IFERROR(MATCH(E34,{"Low","Low-Moderate","Moderate","Moderate-High","High","Exceptional"},0),"") -> 5 | G34: Estimated | H34: BIAL / Bangalore Traffic Management Plan (2025)
A35: 25 | B35: Intelligent Systems & Hubs | C35: Roadways Inter-State Connections (Outstation Bus Stands) | D35: High Density Outstations | E35: High | F35: =IFERROR(MATCH(E35,{"Low","Low-Moderate","Moderate","Moderate-High","High","Exceptional"},0),"") -> 5 | G35: Official source | H35: BIAL / Bangalore Traffic Management Plan (2025)
A36: 26 | B36: Intelligent Systems & Hubs | C36: Railway Connectivity (Outstation Rail Terminals Layout) | D36: Saraswathipura Hub Complex | E36: High | F36: =IFERROR(MATCH(E36,{"Low","Low-Moderate","Moderate","Moderate-High","High","Exceptional"},0),"") -> 5 | G36: Official source | H36: BIAL / Bangalore Traffic Management Plan (2025)
A37: Parking Management
A38: 27 | B38: Parking Management | C38: Multilevel Parking Facilities (Active Structure Count) | D38: 6 MLCP Operational Units | E38: Moderate | F38: =IFERROR(MATCH(E38,{"Low","Low-Moderate","Moderate","Moderate-High","High","Exceptional"},0),"") -> 3 | G38: Estimated | H38: BBMP / DULT Smart Parking Status Reports (2025)
A39: 28 | B39: Parking Management | C39: Parking Density (Spaces per Vehicle/Area) | D39: 0.38 spaces/vehicle | E39: Moderate | F39: =IFERROR(MATCH(E39,{"Low","Low-Moderate","Moderate","Moderate-High","High","Exceptional"},0),"") -> 3 | G39: Estimated | H39: BBMP / DULT Smart Parking Status Reports (2025)
A40: 29 | B40: Parking Management | C40: Parking Coverage (Major Commercial Areas Served) | D40: CBD Zones Smart Parking Connected | E40: Moderate-High | F40: =IFERROR(MATCH(E40,{"Low","Low-Moderate","Moderate","Moderate-High","High","Exceptional"},0),"") -> 4 | G40: Estimated | H40: BBMP / DULT Smart Parking Status Reports (2025)
A41: 30 | B41: Parking Management | C41: Distance to Parking (Avg Walk to Destination) | D41: 300 meters | E41: Moderate | F41: =IFERROR(MATCH(E41,{"Low","Low-Moderate","Moderate","Moderate-High","High","Exceptional"},0),"") -> 3 | G41: Estimated | H41: BBMP / DULT Smart Parking Status Reports (2025)
...

Sheet Social Infrastructure
A1: Bangalore — Social Infrastructure
A2: Values and ratings from the corrected Urban Planning Data Atlas workbooks (Oct 2026). Ratings rank the city against the other seven Atlas cities. Rating score: 6 = Exceptional … 1 = Low.
A4: S.No | B4: Topic | C4: Indicator | D4: Value | E4: Rating | F4: Rating score (1–6) | G4: Data basis | H4: Source & timeline | I4: Verification note
A5: Inclusive Living
A6: 1 | B6: Inclusive Living | C6: Slum vs City Area Change Rate | D6: -2.1% / +4.8% | E6: High | F6: =IFERROR(MATCH(E6,{"Low","Low-Moderate","Moderate","Moderate-High","High","Exceptional"},0),"") -> 5 | G6: Estimated | H6: BBMP / Karnataka Slum Development Board (2024)
A7: 2 | B7: Inclusive Living | C7: Slum Population Proportion | D7: 8.2% | E7: High | F7: =IFERROR(MATCH(E7,{"Low","Low-Moderate","Moderate","Moderate-High","High","Exceptional"},0),"") -> 5 | G7: Official source | H7: BBMP / Karnataka Slum Development Board (2024) | I7: Verified: Matches Census 2011 (8.4%).
A8: 3 | B8: Inclusive Living | C8: Access to Formal Housing Post-Redevelopment | D8: 82% | E8: High | F8: =IFERROR(MATCH(E8,{"Low","Low-Moderate","Moderate","Moderate-High","High","Exceptional"},0),"") -> 5 | G8: Estimated | H8: BBMP / Karnataka Slum Development Board (2024)
A9: Quality of Life
A10: 4 | B10: Quality of Life | C10: Access to Basic Services (%) | D10: 85% | E10: High | F10: =IFERROR(MATCH(E10,{"Low","Low-Moderate","Moderate","Moderate-High","High","Exceptional"},0),"") -> 5 | G10: Estimated | H10: DULT / BBMP Quality of Life Trackers (2025)
A11: 5 | B11: Quality of Life | C11: Travel Congestion Index | D11: 1.74x | E11: Low-Moderate | F11: =IFERROR(MATCH(E11,{"Low","Low-Moderate","Moderate","Moderate-High","High","Exceptional"},0),"") -> 2 | G11: Third-party source | H11: DULT / BBMP Quality of Life Trackers (2025) | I11: Corrected: TomTom Traffic Index 2025 congestion level 74.4%.
A12: 6 | B12: Quality of Life | C12: Citizen Satisfaction Rating (/5) | D12: 3.8 / 5.0 | E12: High | F12: =IFERROR(MATCH(E12,{"Low","Low-Moderate","Moderate","Moderate-High","High","Exceptional"},0),"") -> 5 | G12: Unverifiable | H12: DULT / BBMP Quality of Life Trackers (2025) | I12: Unverified: No published 2023–24 citizen survey behind this value.
A13: Innovation & Knowledge
A14: 7 | B14: Innovation & Knowledge | C14: Startup Incubators supported | D14: 160 | E14: Exceptional | F14: =IFERROR(MATCH(E14,{"Low","Low-Moderate","Moderate","Moderate-High","High","Exceptional"},0),"") -> 6 | G14: Estimated | H14: Startup India Dashboard / NIRF / IISc Reports (2025) | I14: Harmonised: Harmonised with Economic Opportunities sheet ii) indicator (b), the narrow incubator count.
A15: 8 | B15: Innovation & Knowledge | C15: NIRF Ranked Institutes Count | D15: 18 | E15: High | F15: =IFERROR(MATCH(E15,{"Low","Low-Moderate","Moderate","Moderate-High","High","Exceptional"},0),"") -> 5 | G15: Official source | H15: Startup India Dashboard / NIRF / IISc Reports (2025)
A16: 9 | B16: Innovation & Knowledge | C16: CFTI & SFTI Institutions | D16: 8 | E16: Not rated | F16: =IFERROR(MATCH(E16,{"Low","Low-Moderate","Moderate","Moderate-High","High","Exceptional"},0),"") | G16: Official source | H16: Startup India Dashboard / NIRF / IISc Reports (2025)
A17: 10 | B17: Innovation & Knowledge | C17: NIRF Score Average | D17: 61.5 | E17: High | F17: =IFERROR(MATCH(E17,{"Low","Low-Moderate","Moderate","Moderate-High","High","Exceptional"},0),"") -> 5 | G17: Derived / calculated | H17: Startup India Dashboard / NIRF / IISc Reports (2025)
A18: Food Security
A19: 11 | B19: Food Security | C19: Ration Shops per 10,000 Population | D19: 1.4 | E19: Moderate | F19: =IFERROR(MATCH(E19,{"Low","Low-Moderate","Moderate","Moderate-High","High","Exceptional"},0),"") -> 3 | G19: Derived / calculated | H19: Food & Civil Supplies Dept Karnataka (2024)
A20: 12 | B20: Food Security | C20: PDS System Digital Infrastructure Access | D20: Ahara Karnataka PDS Portal | E20: Moderate-High | F20: =IFERROR(MATCH(E20,{"Low","Low-Moderate","Moderate","Moderate-High","High","Exceptional"},0),"") -> 4 | G20: Estimated | H20: Food & Civil Supplies Dept Karnataka (2024)
A21: Culture & Green Spaces
A22: 13 | B22: Culture & Green Spaces | C22: Recreational Area Per Capita | D22: 6.8 sq.m | E22: High | F22: =IFERROR(MATCH(E22,{"Low","Low-Moderate","Moderate","Moderate-High","High","Exceptional"},0),"") -> 5 | G22: Estimated | H22: BBMP Horticulture / IISc Urban Canopy Studies (2025)
A23: 14 | B23: Culture & Green Spaces | C23: User Satisfaction Score (/5) | D23: 4.1 / 5.0 | E23: High | F23: =IFERROR(MATCH(E23,{"Low","Low-Moderate","Moderate","Moderate-High","High","Exceptional"},0),"") -> 5 | G23: Unverifiable | H23: BBMP Horticulture / IISc Urban Canopy Studies (2025)
A24: Sports & Wellness
A25: 15 | B25: Sports & Wellness | C25: Total Registered Sports Facilities | D25: 36 | E25: High | F25: =IFERROR(MATCH(E25,{"Low","Low-Moderate","Moderate","Moderate-High","High","Exceptional"},0),"") -> 5 | G25: Estimated | H25: Karnataka Youth Empowerment & Sports Dept (2025)
A26: 16 | B26: Sports & Wellness | C26: High-Performance Training Centers | D26: 4 (Kanteerava, Padukone-Dravid Centre) | E26: High | F26: =IFERROR(MATCH(E26,{"Low","Low-Moderate","Moderate","Moderate-High","High","Exceptional"},0),"") -> 5 | G26: Estimated | H26: Karnataka Youth Empowerment & Sports Dept (2025)
A27: Universal Accessibility
A28: 17 | B28: Universal Accessibility | C28: Accessible Public Buildings (%) | D28: 48% | E28: Moderate | F28: =IFERROR(MATCH(E28,{"Low","Low-Moderate","Moderate","Moderate-High","High","Exceptional"},0),"") -> 3 | G28: Estimated | H28: BBMP Smart City / DULT Walkability Framework (2025)
A29: 18 | B29: Universal Accessibility | C29: Accessible Transport Infra (%) | D29: 55% | E29: Moderate | F29: =IFERROR(MATCH(E29,{"Low","Low-Moderate","Moderate","Moderate-High","High","Exceptional"},0),"") -> 3 | G29: Estimated | H29: BBMP Smart City / DULT Walkability Framework (2025)
A30: 19 | B30: Universal Accessibility | C30: Universal Walkability Score (/100) | D30: 52 / 100 | E30: High | F30: =IFERROR(MATCH(E30,{"Low","Low-Moderate","Moderate","Moderate-High","High","Exceptional"},0),"") -> 5 | G30: Unverifiable | H30: BBMP Smart City / DULT Walkability Framework (2025)
A31: Child & Elderly Support
A32: 20 | B32: Child & Elderly Support | C32: Facility Density (Per 100k Target Pop) | D32: 1.9 | E32: High | F32: =IFERROR(MATCH(E32,{"Low","Low-Moderate","Moderate","Moderate-High","High","Exceptional"},0),"") -> 5 | G32: Estimated | H32: Karnataka Social Justice Portal / BBMP (2025)
A33: 21 | B33: Child & Elderly Support | C33: Capacity per Target Pop (%) | D33: 82% | E33: High | F33: =IFERROR(MATCH(E33,{"Low","Low-Moderate","Moderate","Moderate-High","High","Exceptional"},0),"") -> 5 | G33: Estimated | H33: Karnataka Social Justice Portal / BBMP (2025)
A34: 22 | B34: Child & Elderly Support | C34: Funding per Beneficiary (Annual) | D34: ₹14,200 | E34: High | F34: =IFERROR(MATCH(E34,{"Low","Low-Moderate","Moderate","Moderate-High","High","Exceptional"},0),"") -> 5 | G34: Estimated | H34: Karnataka Social Justice Portal / BBMP (2025)
A35: 23 | B35: Child & Elderly Support | C35: Gender-Sensitive Care Provision | D35: Advanced | E35: High | F35: =IFERROR(MATCH(E35,{"Low","Low-Moderate","Moderate","Moderate-High","High","Exceptional"},0),"") -> 5 | G35: Estimated | H35: Karnataka Social Justice Portal / BBMP (2025)
A36: Foundational Education
A37: 24 | B37: Foundational Education | C37: Infrastructure Adequacy Index | D37: 78 / 100 | E37: Moderate-High | F37: =IFERROR(MATCH(E37,{"Low","Low-Moderate","Moderate","Moderate-High","High","Exceptional"},0),"") -> 4 | G37: Unverifiable | H37: Karnataka Education Dept / BBMP Infrastructure (2025)
A38: 25 | B38: Foundational Education | C38: Advanced Educational Infra Availability | D38: 68% | E38: High | F38: =IFERROR(MATCH(E38,{"Low","Low-Moderate","Moderate","Moderate-High","High","Exceptional"},0),"") -> 5 | G38: Estimated | H38: Karnataka Education Dept / BBMP Infrastructure (2025)
A39: 26 | B39: Foundational Education | C39: Senior Secondary Completion Rate | D39: 84% | E39: Not rated | F39: =IFERROR(MATCH(E39,{"Low","Low-Moderate","Moderate","Moderate-High","High","Exceptional"},0),"") | G39: Estimated | H39: Karnataka Education Dept / BBMP Infrastructure (2025)
A40: 27 | B40: Foundational Education | C40: Higher Education Completion Rate | D40: 79% | E40: Not rated | F40: =IFERROR(MATCH(E40,{"Low","Low-Moderate","Moderate","Moderate-High","High","Exceptional"},0),"") | G40: Estimated | H40: Karnataka Education Dept / BBMP Infrastructure (2025)
A41: 28 | B41: Foundational Education | C41: Dropout Rate (%) | D41: 2.1% | E41: Not rated | F41: =IFERROR(MATCH(E41,{"Low","Low-Moderate","Moderate","Moderate-High","High","Exceptional"},0),"") | G41: Estimated | H41: Karnataka Education Dept / BBMP Infrastructure (2025)
...

Sheet Urban Infrastructure
A1: Bangalore — Urban Infrastructure
A2: Values and ratings from the corrected Urban Planning Data Atlas workbooks (Oct 2026). Ratings rank the city against the other seven Atlas cities. Rating score: 6 = Exceptional … 1 = Low.
A4: S.No | B4: Topic | C4: Indicator | D4: Value | E4: Rating | F4: Rating score (1–6) | G4: Data basis | H4: Source & timeline | I4: Verification note
A5: Sanitation & Toilets
A6: 1 | B6: Sanitation & Toilets | C6: Public Toilets (Per 1k Pop/sq.km) | D6: 1.4 | E6: Moderate | F6: =IFERROR(MATCH(E6,{"Low","Low-Moderate","Moderate","Moderate-High","High","Exceptional"},0),"") -> 3 | G6: Estimated | H6: BBMP Swachh Bharat Cell Dashboard (2025)
A7: 2 | B7: Sanitation & Toilets | C7: Markets/Hubs with Toilet Access (%) | D7: 88% | E7: Moderate-High | F7: =IFERROR(MATCH(E7,{"Low","Low-Moderate","Moderate","Moderate-High","High","Exceptional"},0),"") -> 4 | G7: Estimated | H7: BBMP Swachh Bharat Cell Dashboard (2025)
A8: 3 | B8: Sanitation & Toilets | C8: Accessible for PwD Users (%) | D8: 58% | E8: Moderate | F8: =IFERROR(MATCH(E8,{"Low","Low-Moderate","Moderate","Moderate-High","High","Exceptional"},0),"") -> 3 | G8: Estimated | H8: BBMP Swachh Bharat Cell Dashboard (2025)
A9: 4 | B9: Sanitation & Toilets | C9: Inspection Cleanliness Score (Out of 5.0) | D9: 3.7 / 5.0 | E9: Moderate | F9: =IFERROR(MATCH(E9,{"Low","Low-Moderate","Moderate","Moderate-High","High","Exceptional"},0),"") -> 3 | G9: Unverifiable | H9: BBMP Swachh Bharat Cell Dashboard (2025)
A10: 5 | B10: Sanitation & Toilets | C10: Slums/EWS Areas with Toilet Access (%) | D10: 78% | E10: Moderate | F10: =IFERROR(MATCH(E10,{"Low","Low-Moderate","Moderate","Moderate-High","High","Exceptional"},0),"") -> 3 | G10: Estimated | H10: BBMP Swachh Bharat Cell Dashboard (2025)
A11: Potable Water Supply
A12: 6 | B12: Potable Water Supply | C12: Potable Water Supplied (Per Capita / Day) | D12: 110 L | E12: Low-Moderate | F12: =IFERROR(MATCH(E12,{"Low","Low-Moderate","Moderate","Moderate-High","High","Exceptional"},0),"") -> 2 | G12: Estimated | H12: BWSSB Cauvery Phase-V Progress Matrix (2025)
A13: 7 | B13: Potable Water Supply | C13: Households with Smart/ Prepaid Meters (%) | D13: 28% | E13: High | F13: =IFERROR(MATCH(E13,{"Low","Low-Moderate","Moderate","Moderate-High","High","Exceptional"},0),"") -> 5 | G13: Estimated | H13: BWSSB Cauvery Phase-V Progress Matrix (2025)
A14: 8 | B14: Potable Water Supply | C14: Total Installed WTP Capacity (MLD) | D14: 1850 MLD | E14: Not rated | F14: =IFERROR(MATCH(E14,{"Low","Low-Moderate","Moderate","Moderate-High","High","Exceptional"},0),"") | G14: Estimated | H14: BWSSB Cauvery Phase-V Progress Matrix (2025)
A15: 9 | B15: Potable Water Supply | C15: Supply Deficit Index ((Demand-Supply)/Dem %) | D15: 18.2% | E15: Low | F15: =IFERROR(MATCH(E15,{"Low","Low-Moderate","Moderate","Moderate-High","High","Exceptional"},0),"") -> 1 | G15: Estimated | H15: BWSSB Cauvery Phase-V Progress Matrix (2025)
A16: 10 | B16: Potable Water Supply | C16: Households Connected to Piped Water (%) | D16: 64% | E16: Low-Moderate | F16: =IFERROR(MATCH(E16,{"Low","Low-Moderate","Moderate","Moderate-High","High","Exceptional"},0),"") -> 2 | G16: Official source | H16: BWSSB Cauvery Phase-V Progress Matrix (2025)
A17: 11 | B17: Potable Water Supply | C17: Average Supply Hours (Per Day) | D17: 2.0 hrs | E17: Low | F17: =IFERROR(MATCH(E17,{"Low","Low-Moderate","Moderate","Moderate-High","High","Exceptional"},0),"") -> 1 | G17: Estimated | H17: BWSSB Cauvery Phase-V Progress Matrix (2025)
A18: Energy Supply & Reliability
